Workbook

Sheet Overview
B1: ="OPS readiness – report "&TEXT(DATEVALUE('Thong tin'!$A$2),"d mmm yyyy")
B2: Live view of the data tables in this workbook. Edit the numbers in the data sheets (after "Huong dan"); this page recalculates at once.
B3: ="Manpower in "&TEXT(DATEVALUE(LOOKUP(2,1/('Nhan su theo thang'!$G$2:$G$300<>""),'Nhan su theo thang'!$A$2:$A$300)&"-01"),"mmm yyyy")&": "&LOOKUP(2,1/('Nhan su theo thang'!$G$2:$G$300<>""),'Nhan su theo thang'!$G$2:$G$300)&" / "&LOOKUP(2,1/('Nhan su theo thang'!$G$2:$G$300<>""),'Nhan su theo thang'!$F$2:$F$300)&" people against plan; OPS teams ORR checklist at "&TEXT(LOOKUP(2,1/('ORR theo thang'!$C$2:$C$300<>""),'ORR theo thang'!$C$2:$C$300)/100,"0.0%")&" vs plan "&TEXT(LOOKUP(2,1/('ORR theo thang'!$C$2:$C$300<>""),'ORR theo thang'!$B$2:$B$300)/100,"0.0%")&"; "&SUMIFS('PR dang xu ly'!$C$2:$C$300,'PR dang xu ly'!$B$2:$B$300,"Late")&" PRs late."
B5: ="OPS manpower · "&TEXT(DATEVALUE(LOOKUP(2,1/('Nhan su theo thang'!$G$2:$G$300<>""),'Nhan su theo thang'!$A$2:$A$300)&"-01"),"mmm yyyy") | F5: ="OPS teams ORR checklist · "&TEXT(DATEVALUE(LOOKUP(2,1/('ORR theo thang'!$C$2:$C$300<>""),'ORR theo thang'!$A$2:$A$300)&"-01"),"mmm yyyy") | J5: CBTA development (CPP & WHP) | N5: Mandatory training · offshore | R5: Procedures · HSE | general operations | V5: PRs in progress
B6: =LOOKUP(2,1/('Nhan su theo thang'!$G$2:$G$300<>""),'Nhan su theo thang'!$G$2:$G$300) | F6: =LOOKUP(2,1/('ORR theo thang'!$C$2:$C$300<>""),'ORR theo thang'!$C$2:$C$300)/100 | J6: =AVERAGE(SUMIFS('CBTA'!$F$2:$F$300,'CBTA'!$A$2:$A$300,"CPP")/SUMIFS('CBTA'!$C$2:$C$300,'CBTA'!$A$2:$A$300,"CPP"),SUMIFS('CBTA'!$F$2:$F$300,'CBTA'!$A$2:$A$300,"WHP")/SUMIFS('CBTA'!$C$2:$C$300,'CBTA'!$A$2:$A$300,"WHP")) | N6: =SUM('Dao tao bat buoc'!$C$2:$C$300)/SUM('Dao tao bat buoc'!$B$2:$B$300) | R6: =TEXT(AVERAGEIFS('Quy trinh'!$H$2:$H$300,'Quy trinh'!$B$2:$B$300,"HSE")/100,"0%")&" | "&TEXT(AVERAGEIFS('Quy trinh'!$H$2:$H$300,'Quy trinh'!$B$2:$B$300,"General operations")/100,"0%") | V6: =SUM('PR dang xu ly'!$C$2:$C$300)
B7: =TEXT(LOOKUP(2,1/('Nhan su theo thang'!$G$2:$G$300<>""),'Nhan su theo thang'!$G$2:$G$300)/LOOKUP(2,1/('Nhan su theo thang'!$G$2:$G$300<>""),'Nhan su theo thang'!$F$2:$F$300),"0%")&" of monthly plan ("&LOOKUP(2,1/('Nhan su theo thang'!$G$2:$G$300<>""),'Nhan su theo thang'!$F$2:$F$300)&")" | F7: ="Plan "&TEXT(LOOKUP(2,1/('ORR theo thang'!$C$2:$C$300<>""),'ORR theo thang'!$B$2:$B$300)/100,"0.0%")&" · "&IF(LOOKUP(2,1/('ORR theo thang'!$C$2:$C$300<>""),'ORR theo thang'!$C$2:$C$300)>=LOOKUP(2,1/('ORR theo thang'!$C$2:$C$300<>""),'ORR theo thang'!$B$2:$B$300),"+","")&TEXT(LOOKUP(2,1/('ORR theo thang'!$C$2:$C$300<>""),'ORR theo thang'!$C$2:$C$300)-LOOKUP(2,1/('ORR theo thang'!$C$2:$C$300<>""),'ORR theo thang'!$B$2:$B$300),"0.0")&" pts" | J7: ="Theory assessment "&TEXT(AVERAGE(AVERAGEIFS('CBTA'!$G$2:$G$300,'CBTA'!$A$2:$A$300,"CPP"),AVERAGEIFS('CBTA'!$G$2:$G$300,'CBTA'!$A$2:$A$300,"WHP"))/100,"0.0%")&" · OJT "&TEXT(AVERAGE(AVERAGEIFS('CBTA'!$I$2:$I$300,'CBTA'!$A$2:$A$300,"CPP"),AVERAGEIFS('CBTA'!$I$2:$I$300,'CBTA'!$A$2:$A$300,"WHP"))/100,"0.0%") | N7: =TEXT(SUM('Dao tao bat buoc'!$C$2:$C$300),"#,##0")&" / "&TEXT(SUM('Dao tao bat buoc'!$B$2:$B$300),"#,##0")&" courses completed" | R7: =COUNTIFS('Quy trinh'!$E$2:$E$300,"<>Yes",'Quy trinh'!$C$2:$C$300,"<>")&" procedures not yet issued" | V7: =SUMIFS('PR dang xu ly'!$C$2:$C$300,'PR dang xu ly'!$B$2:$B$300,"Late")&" late · "&SUMIFS('PR dang xu ly'!$C$2:$C$300,'PR dang xu ly'!$B$2:$B$300,"Near-late")&" near-late · "&SUMIFS('Goi chua co PR'!$C$2:$C$300,'Goi chua co PR'!$A$2:$A$300,"status")&" packages without PR"
B28: Current staffing
B29: Filled / required positions at the report date.
B30: Group | D30: Filled | E30: Required | F30: Filled %
B31: =IF(INDEX('Dinh bien'!$A$2:$A$300,1)="","",INDEX('Dinh bien'!$A$2:$A$300,1)) | D31: =IF(INDEX('Dinh bien'!$B$2:$B$300,1)="","",INDEX('Dinh bien'!$B$2:$B$300,1)) | E31: =IF(INDEX('Dinh bien'!$C$2:$C$300,1)="","",INDEX('Dinh bien'!$C$2:$C$300,1)) | F31: =IF(D31="","",D31/E31)
B32: =IF(INDEX('Dinh bien'!$A$2:$A$300,2)="","",INDEX('Dinh bien'!$A$2:$A$300,2)) | D32: =IF(INDEX('Dinh bien'!$B$2:$B$300,2)="","",INDEX('Dinh bien'!$B$2:$B$300,2)) | E32: =IF(INDEX('Dinh bien'!$C$2:$C$300,2)="","",INDEX('Dinh bien'!$C$2:$C$300,2)) | F32: =IF(D32="","",D32/E32)
B33: =IF(INDEX('Dinh bien'!$A$2:$A$300,3)="","",INDEX('Dinh bien'!$A$2:$A$300,3)) | D33: =IF(INDEX('Dinh bien'!$B$2:$B$300,3)="","",INDEX('Dinh bien'!$B$2:$B$300,3)) | E33: =IF(INDEX('Dinh bien'!$C$2:$C$300,3)="","",INDEX('Dinh bien'!$C$2:$C$300,3)) | F33: =IF(D33="","",D33/E33)
B34: =IF(INDEX('Dinh bien'!$A$2:$A$300,4)="","",INDEX('Dinh bien'!$A$2:$A$300,4)) | D34: =IF(INDEX('Dinh bien'!$B$2:$B$300,4)="","",INDEX('Dinh bien'!$B$2:$B$300,4)) | E34: =IF(INDEX('Dinh bien'!$C$2:$C$300,4)="","",INDEX('Dinh bien'!$C$2:$C$300,4)) | F34: =IF(D34="","",D34/E34)
B35: =IF(INDEX('Dinh bien'!$A$2:$A$300,5)="","",INDEX('Dinh bien'!$A$2:$A$300,5)) | D35: =IF(INDEX('Dinh bien'!$B$2:$B$300,5)="","",INDEX('Dinh bien'!$B$2:$B$300,5)) | E35: =IF(INDEX('Dinh bien'!$C$2:$C$300,5)="","",INDEX('Dinh bien'!$C$2:$C$300,5)) | F35: =IF(D35="","",D35/E35)
B37: ="Vacant positions: "&IFERROR(INDEX('Trang thai cong viec'!$C$2:$C$300,MATCH("Vacant positions",'Trang thai cong viec'!$B$2:$B$300,0)),"—")

Sheet Manpower & Training
B1: ="OPS readiness – report "&TEXT(DATEVALUE('Thong tin'!$A$2),"d mmm yyyy")
B2: Mandatory training, CBTA development and assessment, vendor training schedule.
B4: Mandatory training – PQPOC offshore staff | J4: CBTA by team: development and assessment
B5: Courses completed vs required by the HSE training matrix. Red below 30%. | J5: Modules developed and theory / OJT assessment progress.
B6: Team | D6: Planned | E6: Earned | F6: Balance | G6: Completed % | J6: Platform | K6: Team | L6: Modules | M6: Completed | N6: In dev. | O6: In review | P6: % developed | Q6: % theory | R6: OJT modules | S6: % OJT
B7: =IF(INDEX('Dao tao bat buoc'!$A$2:$A$300,1)="","",INDEX('Dao tao bat buoc'!$A$2:$A$300,1)) | D7: =IF(INDEX('Dao tao bat buoc'!$B$2:$B$300,1)="","",INDEX('Dao tao bat buoc'!$B$2:$B$300,1)) | E7: =IF(INDEX('Dao tao bat buoc'!$C$2:$C$300,1)="","",INDEX('Dao tao bat buoc'!$C$2:$C$300,1)) | F7: =IF(INDEX('Dao tao bat buoc'!$D$2:$D$300,1)="","",INDEX('Dao tao bat buoc'!$D$2:$D$300,1)) | G7: =IF(D7="","",E7/D7) | J7: =IF(INDEX('CBTA'!$A$2:$A$300,1)="","",INDEX('CBTA'!$A$2:$A$300,1)) | K7: =IF(INDEX('CBTA'!$B$2:$B$300,1)="","",INDEX('CBTA'!$B$2:$B$300,1)) | L7: =IF(INDEX('CBTA'!$C$2:$C$300,1)="","",INDEX('CBTA'!$C$2:$C$300,1)) | M7: =IF(INDEX('CBTA'!$F$2:$F$300,1)="","",INDEX('CBTA'!$F$2:$F$300,1)) | N7: =IF(INDEX('CBTA'!$D$2:$D$300,1)="","",INDEX('CBTA'!$D$2:$D$300,1)) | O7: =IF(INDEX('CBTA'!$E$2:$E$300,1)="","",INDEX('CBTA'!$E$2:$E$300,1)) | P7: =IF(L7="","",M7/L7) | Q7: =IF(J7="","",INDEX('CBTA'!$G$2:$G$300,1)/100) | R7: =IF(INDEX('CBTA'!$H$2:$H$300,1)="","",INDEX('CBTA'!$H$2:$H$300,1)) | S7: =IF(J7="","",INDEX('CBTA'!$I$2:$I$300,1)/100) | W7: =IF(J7="","",J7&" "&K7)
B8: =IF(INDEX('Dao tao bat buoc'!$A$2:$A$300,2)="","",INDEX('Dao tao bat buoc'!$A$2:$A$300,2)) | D8: =IF(INDEX('Dao tao bat buoc'!$B$2:$B$300,2)="","",INDEX('Dao tao bat buoc'!$B$2:$B$300,2)) | E8: =IF(INDEX('Dao tao bat buoc'!$C$2:$C$300,2)="","",INDEX('Dao tao bat buoc'!$C$2:$C$300,2)) | F8: =IF(INDEX('Dao tao bat buoc'!$D$2:$D$300,2)="","",INDEX('Dao tao bat buoc'!$D$2:$D$300,2)) | G8: =IF(D8="","",E8/D8) | J8: =IF(INDEX('CBTA'!$A$2:$A$300,2)="","",INDEX('CBTA'!$A$2:$A$300,2)) | K8: =IF(INDEX('CBTA'!$B$2:$B$300,2)="","",INDEX('CBTA'!$B$2:$B$300,2)) | L8: =IF(INDEX('CBTA'!$C$2:$C$300,2)="","",INDEX('CBTA'!$C$2:$C$300,2)) | M8: =IF(INDEX('CBTA'!$F$2:$F$300,2)="","",INDEX('CBTA'!$F$2:$F$300,2)) | N8: =IF(INDEX('CBTA'!$D$2:$D$300,2)="","",INDEX('CBTA'!$D$2:$D$300,2)) | O8: =IF(INDEX('CBTA'!$E$2:$E$300,2)="","",INDEX('CBTA'!$E$2:$E$300,2)) | P8: =IF(L8="","",M8/L8) | Q8: =IF(J8="","",INDEX('CBTA'!$G$2:$G$300,2)/100) | R8: =IF(INDEX('CBTA'!$H$2:$H$300,2)="","",INDEX('CBTA'!$H$2:$H$300,2)) | S8: =IF(J8="","",INDEX('CBTA'!$I$2:$I$300,2)/100) | W8: =IF(J8="","",J8&" "&K8)
B9: =IF(INDEX('Dao tao bat buoc'!$A$2:$A$300,3)="","",INDEX('Dao tao bat buoc'!$A$2:$A$300,3)) | D9: =IF(INDEX('Dao tao bat buoc'!$B$2:$B$300,3)="","",INDEX('Dao tao bat buoc'!$B$2:$B$300,3)) | E9: =IF(INDEX('Dao tao bat buoc'!$C$2:$C$300,3)="","",INDEX('Dao tao bat buoc'!$C$2:$C$300,3)) | F9: =IF(INDEX('Dao tao bat buoc'!$D$2:$D$300,3)="","",INDEX('Dao tao bat buoc'!$D$2:$D$300,3)) | G9: =IF(D9="","",E9/D9) | J9: =IF(INDEX('CBTA'!$A$2:$A$300,3)="","",INDEX('CBTA'!$A$2:$A$300,3)) | K9: =IF(INDEX('CBTA'!$B$2:$B$300,3)="","",INDEX('CBTA'!$B$2:$B$300,3)) | L9: =IF(INDEX('CBTA'!$C$2:$C$300,3)="","",INDEX('CBTA'!$C$2:$C$300,3)) | M9: =IF(INDEX('CBTA'!$F$2:$F$300,3)="","",INDEX('CBTA'!$F$2:$F$300,3)) | N9: =IF(INDEX('CBTA'!$D$2:$D$300,3)="","",INDEX('CBTA'!$D$2:$D$300,3)) | O9: =IF(INDEX('CBTA'!$E$2:$E$300,3)="","",INDEX('CBTA'!$E$2:$E$300,3)) | P9: =IF(L9="","",M9/L9) | Q9: =IF(J9="","",INDEX('CBTA'!$G$2:$G$300,3)/100) | R9: =IF(INDEX('CBTA'!$H$2:$H$300,3)="","",INDEX('CBTA'!$H$2:$H$300,3)) | S9: =IF(J9="","",INDEX('CBTA'!$I$2:$I$300,3)/100) | W9: =IF(J9="","",J9&" "&K9)
B10: =IF(INDEX('Dao tao bat buoc'!$A$2:$A$300,4)="","",INDEX('Dao tao bat buoc'!$A$2:$A$300,4)) | D10: =IF(INDEX('Dao tao bat buoc'!$B$2:$B$300,4)="","",INDEX('Dao tao bat buoc'!$B$2:$B$300,4)) | E10: =IF(INDEX('Dao tao bat buoc'!$C$2:$C$300,4)="","",INDEX('Dao tao bat buoc'!$C$2:$C$300,4)) | F10: =IF(INDEX('Dao tao bat buoc'!$D$2:$D$300,4)="","",INDEX('Dao tao bat buoc'!$D$2:$D$300,4)) | G10: =IF(D10="","",E10/D10) | J10: =IF(INDEX('CBTA'!$A$2:$A$300,4)="","",INDEX('CBTA'!$A$2:$A$300,4)) | K10: =IF(INDEX('CBTA'!$B$2:$B$300,4)="","",INDEX('CBTA'!$B$2:$B$300,4)) | L10: =IF(INDEX('CBTA'!$C$2:$C$300,4)="","",INDEX('CBTA'!$C$2:$C$300,4)) | M10: =IF(INDEX('CBTA'!$F$2:$F$300,4)="","",INDEX('CBTA'!$F$2:$F$300,4)) | N10: =IF(INDEX('CBTA'!$D$2:$D$300,4)="","",INDEX('CBTA'!$D$2:$D$300,4)) | O10: =IF(INDEX('CBTA'!$E$2:$E$300,4)="","",INDEX('CBTA'!$E$2:$E$300,4)) | P10: =IF(L10="","",M10/L10) | Q10: =IF(J10="","",INDEX('CBTA'!$G$2:$G$300,4)/100) | R10: =IF(INDEX('CBTA'!$H$2:$H$300,4)="","",INDEX('CBTA'!$H$2:$H$300,4)) | S10: =IF(J10="","",INDEX('CBTA'!$I$2:$I$300,4)/100) | W10: =IF(J10="","",J10&" "&K10)
B11: =IF(INDEX('Dao tao bat buoc'!$A$2:$A$300,5)="","",INDEX('Dao tao bat buoc'!$A$2:$A$300,5)) | D11: =IF(INDEX('Dao tao bat buoc'!$B$2:$B$300,5)="","",INDEX('Dao tao bat buoc'!$B$2:$B$300,5)) | E11: =IF(INDEX('Dao tao bat buoc'!$C$2:$C$300,5)="","",INDEX('Dao tao bat buoc'!$C$2:$C$300,5)) | F11: =IF(INDEX('Dao tao bat buoc'!$D$2:$D$300,5)="","",INDEX('Dao tao bat buoc'!$D$2:$D$300,5)) | G11: =IF(D11="","",E11/D11) | J11: =IF(INDEX('CBTA'!$A$2:$A$300,5)="","",INDEX('CBTA'!$A$2:$A$300,5)) | K11: =IF(INDEX('CBTA'!$B$2:$B$300,5)="","",INDEX('CBTA'!$B$2:$B$300,5)) | L11: =IF(INDEX('CBTA'!$C$2:$C$300,5)="","",INDEX('CBTA'!$C$2:$C$300,5)) | M11: =IF(INDEX('CBTA'!$F$2:$F$300,5)="","",INDEX('CBTA'!$F$2:$F$300,5)) | N11: =IF(INDEX('CBTA'!$D$2:$D$300,5)="","",INDEX('CBTA'!$D$2:$D$300,5)) | O11: =IF(INDEX('CBTA'!$E$2:$E$300,5)="","",INDEX('CBTA'!$E$2:$E$300,5)) | P11: =IF(L11="","",M11/L11) | Q11: =IF(J11="","",INDEX('CBTA'!$G$2:$G$300,5)/100) | R11: =IF(INDEX('CBTA'!$H$2:$H$300,5)="","",INDEX('CBTA'!$H$2:$H$300,5)) | S11: =IF(J11="","",INDEX('CBTA'!$I$2:$I$300,5)/100) | W11: =IF(J11="","",J11&" "&K11)
B12: =IF(INDEX('Dao tao bat buoc'!$A$2:$A$300,6)="","",INDEX('Dao tao bat buoc'!$A$2:$A$300,6)) | D12: =IF(INDEX('Dao tao bat buoc'!$B$2:$B$300,6)="","",INDEX('Dao tao bat buoc'!$B$2:$B$300,6)) | E12: =IF(INDEX('Dao tao bat buoc'!$C$2:$C$300,6)="","",INDEX('Dao tao bat buoc'!$C$2:$C$300,6)) | F12: =IF(INDEX('Dao tao bat buoc'!$D$2:$D$300,6)="","",INDEX('Dao tao bat buoc'!$D$2:$D$300,6)) | G12: =IF(D12="","",E12/D12) | J12: =IF(INDEX('CBTA'!$A$2:$A$300,6)="","",INDEX('CBTA'!$A$2:$A$300,6)) | K12: =IF(INDEX('CBTA'!$B$2:$B$300,6)="","",INDEX('CBTA'!$B$2:$B$300,6)) | L12: =IF(INDEX('CBTA'!$C$2:$C$300,6)="","",INDEX('CBTA'!$C$2:$C$300,6)) | M12: =IF(INDEX('CBTA'!$F$2:$F$300,6)="","",INDEX('CBTA'!$F$2:$F$300,6)) | N12: =IF(INDEX('CBTA'!$D$2:$D$300,6)="","",INDEX('CBTA'!$D$2:$D$300,6)) | O12: =IF(INDEX('CBTA'!$E$2:$E$300,6)="","",INDEX('CBTA'!$E$2:$E$300,6)) | P12: =IF(L12="","",M12/L12) | Q12: =IF(J12="","",INDEX('CBTA'!$G$2:$G$300,6)/100) | R12: =IF(INDEX('CBTA'!$H$2:$H$300,6)="","",INDEX('CBTA'!$H$2:$H$300,6)) | S12: =IF(J12="","",INDEX('CBTA'!$I$2:$I$300,6)/100) | W12: =IF(J12="","",J12&" "&K12)
B13: =IF(INDEX('Dao tao bat buoc'!$A$2:$A$300,7)="","",INDEX('Dao tao bat buoc'!$A$2:$A$300,7)) | D13: =IF(INDEX('Dao tao bat buoc'!$B$2:$B$300,7)="","",INDEX('Dao tao bat buoc'!$B$2:$B$300,7)) | E13: =IF(INDEX('Dao tao bat buoc'!$C$2:$C$300,7)="","",INDEX('Dao tao bat buoc'!$C$2:$C$300,7)) | F13: =IF(INDEX('Dao tao bat buoc'!$D$2:$D$300,7)="","",INDEX('Dao tao bat buoc'!$D$2:$D$300,7)) | G13: =IF(D13="","",E13/D13) | J13: =IF(INDEX('CBTA'!$A$2:$A$300,7)="","",INDEX('CBTA'!$A$2:$A$300,7)) | K13: =IF(INDEX('CBTA'!$B$2:$B$300,7)="","",INDEX('CBTA'!$B$2:$B$300,7)) | L13: =IF(INDEX('CBTA'!$C$2:$C$300,7)="","",INDEX('CBTA'!$C$2:$C$300,7)) | M13: =IF(INDEX('CBTA'!$F$2:$F$300,7)="","",INDEX('CBTA'!$F$2:$F$300,7)) | N13: =IF(INDEX('CBTA'!$D$2:$D$300,7)="","",INDEX('CBTA'!$D$2:$D$300,7)) | O13: =IF(INDEX('CBTA'!$E$2:$E$300,7)="","",INDEX('CBTA'!$E$2:$E$300,7)) | P13: =IF(L13="","",M13/L13) | Q13: =IF(J13="","",INDEX('CBTA'!$G$2:$G$300,7)/100) | R13: =IF(INDEX('CBTA'!$H$2:$H$300,7)="","",INDEX('CBTA'!$H$2:$H$300,7)) | S13: =IF(J13="","",INDEX('CBTA'!$I$2:$I$300,7)/100) | W13: =IF(J13="","",J13&" "&K13)
B14: =IF(INDEX('Dao tao bat buoc'!$A$2:$A$300,8)="","",INDEX('Dao tao bat buoc'!$A$2:$A$300,8)) | D14: =IF(INDEX('Dao tao bat buoc'!$B$2:$B$300,8)="","",INDEX('Dao tao bat buoc'!$B$2:$B$300,8)) | E14: =IF(INDEX('Dao tao bat buoc'!$C$2:$C$300,8)="","",INDEX('Dao tao bat buoc'!$C$2:$C$300,8)) | F14: =IF(INDEX('Dao tao bat buoc'!$D$2:$D$300,8)="","",INDEX('Dao tao bat buoc'!$D$2:$D$300,8)) | G14: =IF(D14="","",E14/D14) | J14: =IF(INDEX('CBTA'!$A$2:$A$300,8)="","",INDEX('CBTA'!$A$2:$A$300,8)) | K14: =IF(INDEX('CBTA'!$B$2:$B$300,8)="","",INDEX('CBTA'!$B$2:$B$300,8)) | L14: =IF(INDEX('CBTA'!$C$2:$C$300,8)="","",INDEX('CBTA'!$C$2:$C$300,8)) | M14: =IF(INDEX('CBTA'!$F$2:$F$300,8)="","",INDEX('CBTA'!$F$2:$F$300,8)) | N14: =IF(INDEX('CBTA'!$D$2:$D$300,8)="","",INDEX('CBTA'!$D$2:$D$300,8)) | O14: =IF(INDEX('CBTA'!$E$2:$E$300,8)="","",INDEX('CBTA'!$E$2:$E$300,8)) | P14: =IF(L14="","",M14/L14) | Q14: =IF(J14="","",INDEX('CBTA'!$G$2:$G$300,8)/100) | R14: =IF(INDEX('CBTA'!$H$2:$H$300,8)="","",INDEX('CBTA'!$H$2:$H$300,8)) | S14: =IF(J14="","",INDEX('CBTA'!$I$2:$I$300,8)/100) | W14: =IF(J14="","",J14&" "&K14)
B15: =IF(INDEX('Dao tao bat buoc'!$A$2:$A$300,9)="","",INDEX('Dao tao bat buoc'!$A$2:$A$300,9)) | D15: =IF(INDEX('Dao tao bat buoc'!$B$2:$B$300,9)="","",INDEX('Dao tao bat buoc'!$B$2:$B$300,9)) | E15: =IF(INDEX('Dao tao bat buoc'!$C$2:$C$300,9)="","",INDEX('Dao tao bat buoc'!$C$2:$C$300,9)) | F15: =IF(INDEX('Dao tao bat buoc'!$D$2:$D$300,9)="","",INDEX('Dao tao bat buoc'!$D$2:$D$300,9)) | G15: =IF(D15="","",E15/D15) | J15: =IF(INDEX('CBTA'!$A$2:$A$300,9)="","",INDEX('CBTA'!$A$2:$A$300,9)) | K15: =IF(INDEX('CBTA'!$B$2:$B$300,9)="","",INDEX('CBTA'!$B$2:$B$300,9)) | L15: =IF(INDEX('CBTA'!$C$2:$C$300,9)="","",INDEX('CBTA'!$C$2:$C$300,9)) | M15: =IF(INDEX('CBTA'!$F$2:$F$300,9)="","",INDEX('CBTA'!$F$2:$F$300,9)) | N15: =IF(INDEX('CBTA'!$D$2:$D$300,9)="","",INDEX('CBTA'!$D$2:$D$300,9)) | O15: =IF(INDEX('CBTA'!$E$2:$E$300,9)="","",INDEX('CBTA'!$E$2:$E$300,9)) | P15: =IF(L15="","",M15/L15) | Q15: =IF(J15="","",INDEX('CBTA'!$G$2:$G$300,9)/100) | R15: =IF(INDEX('CBTA'!$H$2:$H$300,9)="","",INDEX('CBTA'!$H$2:$H$300,9)) | S15: =IF(J15="","",INDEX('CBTA'!$I$2:$I$300,9)/100) | W15: =IF(J15="","",J15&" "&K15)
B16: =IF(INDEX('Dao tao bat buoc'!$A$2:$A$300,10)="","",INDEX('Dao tao bat buoc'!$A$2:$A$300,10)) | D16: =IF(INDEX('Dao tao bat buoc'!$B$2:$B$300,10)="","",INDEX('Dao tao bat buoc'!$B$2:$B$300,10)) | E16: =IF(INDEX('Dao tao bat buoc'!$C$2:$C$300,10)="","",INDEX('Dao tao bat buoc'!$C$2:$C$300,10)) | F16: =IF(INDEX('Dao tao bat buoc'!$D$2:$D$300,10)="","",INDEX('Dao tao bat buoc'!$D$2:$D$300,10)) | G16: =IF(D16="","",E16/D16) | J16: =IF(INDEX('CBTA'!$A$2:$A$300,10)="","",INDEX('CBTA'!$A$2:$A$300,10)) | K16: =IF(INDEX('CBTA'!$B$2:$B$300,10)="","",INDEX('CBTA'!$B$2:$B$300,10)) | L16: =IF(INDEX('CBTA'!$C$2:$C$300,10)="","",INDEX('CBTA'!$C$2:$C$300,10)) | M16: =IF(INDEX('CBTA'!$F$2:$F$300,10)="","",INDEX('CBTA'!$F$2:$F$300,10)) | N16: =IF(INDEX('CBTA'!$D$2:$D$300,10)="","",INDEX('CBTA'!$D$2:$D$300,10)) | O16: =IF(INDEX('CBTA'!$E$2:$E$300,10)="","",INDEX('CBTA'!$E$2:$E$300,10)) | P16: =IF(L16="","",M16/L16) | Q16: =IF(J16="","",INDEX('CBTA'!$G$2:$G$300,10)/100) | R16: =IF(INDEX('CBTA'!$H$2:$H$300,10)="","",INDEX('CBTA'!$H$2:$H$300,10)) | S16: =IF(J16="","",INDEX('CBTA'!$I$2:$I$300,10)/100) | W16: =IF(J16="","",J16&" "&K16)
B17: Total | D17: =SUM(D7:D16) | E17: =SUM(E7:E16) | F17: =SUM(F7:F16) | G17: =IF(D17=0,"",E17/D17)
J20: Vendor training schedule
J21: Period = month (YYYY-MM) or year.
J22: Period | L22: Course
J23: =IF(INDEX('Dao tao vendor'!$B$2:$B$300,1)="","",INDEX('Dao tao vendor'!$B$2:$B$300,1)) | L23: =IF(INDEX('Dao tao vendor'!$A$2:$A$300,1)="","",INDEX('Dao tao vendor'!$A$2:$A$300,1))
J24: =IF(INDEX('Dao tao vendor'!$B$2:$B$300,2)="","",INDEX('Dao tao vendor'!$B$2:$B$300,2)) | L24: =IF(INDEX('Dao tao vendor'!$A$2:$A$300,2)="","",INDEX('Dao tao vendor'!$A$2:$A$300,2))
J25: =IF(INDEX('Dao tao vendor'!$B$2:$B$300,3)="","",INDEX('Dao tao vendor'!$B$2:$B$300,3)) | L25: =IF(INDEX('Dao tao vendor'!$A$2:$A$300,3)="","",INDEX('Dao tao vendor'!$A$2:$A$300,3))
J26: =IF(INDEX('Dao tao vendor'!$B$2:$B$300,4)="","",INDEX('Dao tao vendor'!$B$2:$B$300,4)) | L26: =IF(INDEX('Dao tao vendor'!$A$2:$A$300,4)="","",INDEX('Dao tao vendor'!$A$2:$A$300,4))
J27: =IF(INDEX('Dao tao vendor'!$B$2:$B$300,5)="","",INDEX('Dao tao vendor'!$B$2:$B$300,5)) | L27: =IF(INDEX('Dao tao vendor'!$A$2:$A$300,5)="","",INDEX('Dao tao vendor'!$A$2:$A$300,5))
J28: =IF(INDEX('Dao tao vendor'!$B$2:$B$300,6)="","",INDEX('Dao tao vendor'!$B$2:$B$300,6)) | L28: =IF(INDEX('Dao tao vendor'!$A$2:$A$300,6)="","",INDEX('Dao tao vendor'!$A$2:$A$300,6))
J29: =IF(INDEX('Dao tao vendor'!$B$2:$B$300,7)="","",INDEX('Dao tao vendor'!$B$2:$B$300,7)) | L29: =IF(INDEX('Dao tao vendor'!$A$2:$A$300,7)="","",INDEX('Dao tao vendor'!$A$2:$A$300,7))
J30: =IF(INDEX('Dao tao vendor'!$B$2:$B$300,8)="","",INDEX('Dao tao vendor'!$B$2:$B$300,8)) | L30: =IF(INDEX('Dao tao vendor'!$A$2:$A$300,8)="","",INDEX('Dao tao vendor'!$A$2:$A$300,8))
J31: =IF(INDEX('Dao tao vendor'!$B$2:$B$300,9)="","",INDEX('Dao tao vendor'!$B$2:$B$300,9)) | L31: =IF(INDEX('Dao tao vendor'!$A$2:$A$300,9)="","",INDEX('Dao tao vendor'!$A$2:$A$300,9))
J32: =IF(INDEX('Dao tao vendor'!$B$2:$B$300,10)="","",INDEX('Dao tao vendor'!$B$2:$B$300,10)) | L32: =IF(INDEX('Dao tao vendor'!$A$2:$A$300,10)="","",INDEX('Dao tao vendor'!$A$2:$A$300,10))
J33: =IF(INDEX('Dao tao vendor'!$B$2:$B$300,11)="","",INDEX('Dao tao vendor'!$B$2:$B$300,11)) | L33: =IF(INDEX('Dao tao vendor'!$A$2:$A$300,11)="","",INDEX('Dao tao vendor'!$A$2:$A$300,11))
J34: =IF(INDEX('Dao tao vendor'!$B$2:$B$300,12)="","",INDEX('Dao tao vendor'!$B$2:$B$300,12)) | L34: =IF(INDEX('Dao tao vendor'!$A$2:$A$300,12)="","",INDEX('Dao tao vendor'!$A$2:$A$300,12))
J35: =IF(INDEX('Dao tao vendor'!$B$2:$B$300,13)="","",INDEX('Dao tao vendor'!$B$2:$B$300,13)) | L35: =IF(INDEX('Dao tao vendor'!$A$2:$A$300,13)="","",INDEX('Dao tao vendor'!$A$2:$A$300,13))
J36: =IF(INDEX('Dao tao vendor'!$B$2:$B$300,14)="","",INDEX('Dao tao vendor'!$B$2:$B$300,14)) | L36: =IF(INDEX('Dao tao vendor'!$A$2:$A$300,14)="","",INDEX('Dao tao vendor'!$A$2:$A$300,14))
J37: =IF(INDEX('Dao tao vendor'!$B$2:$B$300,15)="","",INDEX('Dao tao vendor'!$B$2:$B$300,15)) | L37: =IF(INDEX('Dao tao vendor'!$A$2:$A$300,15)="","",INDEX('Dao tao vendor'!$A$2:$A$300,15))
J38: =IF(INDEX('Dao tao vendor'!$B$2:$B$300,16)="","",INDEX('Dao tao vendor'!$B$2:$B$300,16)) | L38: =IF(INDEX('Dao tao vendor'!$A$2:$A$300,16)="","",INDEX('Dao tao vendor'!$A$2:$A$300,16))
J39: =IF(INDEX('Dao tao vendor'!$B$2:$B$300,17)="","",INDEX('Dao tao vendor'!$B$2:$B$300,17)) | L39: =IF(INDEX('Dao tao vendor'!$A$2:$A$300,17)="","",INDEX('Dao tao vendor'!$A$2:$A$300,17))
J40: =IF(INDEX('Dao tao vendor'!$B$2:$B$300,18)="","",INDEX('Dao tao vendor'!$B$2:$B$300,18)) | L40: =IF(INDEX('Dao tao vendor'!$A$2:$A$300,18)="","",INDEX('Dao tao vendor'!$A$2:$A$300,18))
J41: =IF(INDEX('Dao tao vendor'!$B$2:$B$300,19)="","",INDEX('Dao tao vendor'!$B$2:$B$300,19)) | L41: =IF(INDEX('Dao tao vendor'!$A$2:$A$300,19)="","",INDEX('Dao tao vendor'!$A$2:$A$300,19))
J42: =IF(INDEX('Dao tao vendor'!$B$2:$B$300,20)="","",INDEX('Dao tao vendor'!$B$2:$B$300,20)) | L42: =IF(INDEX('Dao tao vendor'!$A$2:$A$300,20)="","",INDEX('Dao tao vendor'!$A$2:$A$300,20))
J43: =IF(INDEX('Dao tao vendor'!$B$2:$B$300,21)="","",INDEX('Dao tao vendor'!$B$2:$B$300,21)) | L43: =IF(INDEX('Dao tao vendor'!$A$2:$A$300,21)="","",INDEX('Dao tao vendor'!$A$2:$A$300,21))
...

Sheet ORR
B1: ="OPS readiness – report "&TEXT(DATEVALUE('Thong tin'!$A$2),"d mmm yyyy")
B2: ORR checklist: group totals, progress by OPS team and by checklist element.
B4: ="Whole checklist · "&INDEX('ORR tong nhom'!$B$2:$B$300,MATCH("TOTAL",'ORR tong nhom'!$A$2:$A$300,0))&" items" | F4: ="People · "&INDEX('ORR tong nhom'!$B$2:$B$300,MATCH("PEOPLE",'ORR tong nhom'!$A$2:$A$300,0))&" items" | J4: ="Plant · "&INDEX('ORR tong nhom'!$B$2:$B$300,MATCH("PLANT",'ORR tong nhom'!$A$2:$A$300,0))&" items" | N4: ="Process · "&INDEX('ORR tong nhom'!$B$2:$B$300,MATCH("PROCESS",'ORR tong nhom'!$A$2:$A$300,0))&" items"
B5: =INDEX('ORR tong nhom'!$C$2:$C$300,MATCH("TOTAL",'ORR tong nhom'!$A$2:$A$300,0))/100 | F5: =INDEX('ORR tong nhom'!$C$2:$C$300,MATCH("PEOPLE",'ORR tong nhom'!$A$2:$A$300,0))/100 | J5: =INDEX('ORR tong nhom'!$C$2:$C$300,MATCH("PLANT",'ORR tong nhom'!$A$2:$A$300,0))/100 | N5: =INDEX('ORR tong nhom'!$C$2:$C$300,MATCH("PROCESS",'ORR tong nhom'!$A$2:$A$300,0))/100
B8: ="Progress by OPS team · "&TEXT(DATEVALUE(LOOKUP(2,1/('ORR theo thang'!$C$2:$C$300<>""),'ORR theo thang'!$A$2:$A$300)&"-01"),"mmm yyyy")
B9: Gap = actual – plan, in percentage points. Red when behind plan.
B10: Team | D10: Weight | E10: Activities | F10: Completed | G10: Plan % | H10: Actual % | I10: Gap (pts) | J10: Final plan %
B11: =IF(INDEX('ORR theo team'!$A$2:$A$300,1)="","",INDEX('ORR theo team'!$A$2:$A$300,1)) | D11: =IF(B11="","",INDEX('ORR theo team'!$B$2:$B$300,1)/100) | E11: =IF(INDEX('ORR theo team'!$C$2:$C$300,1)="","",INDEX('ORR theo team'!$C$2:$C$300,1)) | F11: =IF(INDEX('ORR theo team'!$D$2:$D$300,1)="","",INDEX('ORR theo team'!$D$2:$D$300,1)) | G11: =IF(B11="","",INDEX('ORR theo team'!$E$2:$E$300,1)/100) | H11: =IF(B11="","",INDEX('ORR theo team'!$F$2:$F$300,1)/100) | I11: =IF(B11="","",(H11-G11)*100) | J11: =IF(B11="","",INDEX('ORR theo team'!$G$2:$G$300,1)/100)
B12: =IF(INDEX('ORR theo team'!$A$2:$A$300,2)="","",INDEX('ORR theo team'!$A$2:$A$300,2)) | D12: =IF(B12="","",INDEX('ORR theo team'!$B$2:$B$300,2)/100) | E12: =IF(INDEX('ORR theo team'!$C$2:$C$300,2)="","",INDEX('ORR theo team'!$C$2:$C$300,2)) | F12: =IF(INDEX('ORR theo team'!$D$2:$D$300,2)="","",INDEX('ORR theo team'!$D$2:$D$300,2)) | G12: =IF(B12="","",INDEX('ORR theo team'!$E$2:$E$300,2)/100) | H12: =IF(B12="","",INDEX('ORR theo team'!$F$2:$F$300,2)/100) | I12: =IF(B12="","",(H12-G12)*100) | J12: =IF(B12="","",INDEX('ORR theo team'!$G$2:$G$300,2)/100)
B13: =IF(INDEX('ORR theo team'!$A$2:$A$300,3)="","",INDEX('ORR theo team'!$A$2:$A$300,3)) | D13: =IF(B13="","",INDEX('ORR theo team'!$B$2:$B$300,3)/100) | E13: =IF(INDEX('ORR theo team'!$C$2:$C$300,3)="","",INDEX('ORR theo team'!$C$2:$C$300,3)) | F13: =IF(INDEX('ORR theo team'!$D$2:$D$300,3)="","",INDEX('ORR theo team'!$D$2:$D$300,3)) | G13: =IF(B13="","",INDEX('ORR theo team'!$E$2:$E$300,3)/100) | H13: =IF(B13="","",INDEX('ORR theo team'!$F$2:$F$300,3)/100) | I13: =IF(B13="","",(H13-G13)*100) | J13: =IF(B13="","",INDEX('ORR theo team'!$G$2:$G$300,3)/100)
B14: =IF(INDEX('ORR theo team'!$A$2:$A$300,4)="","",INDEX('ORR theo team'!$A$2:$A$300,4)) | D14: =IF(B14="","",INDEX('ORR theo team'!$B$2:$B$300,4)/100) | E14: =IF(INDEX('ORR theo team'!$C$2:$C$300,4)="","",INDEX('ORR theo team'!$C$2:$C$300,4)) | F14: =IF(INDEX('ORR theo team'!$D$2:$D$300,4)="","",INDEX('ORR theo team'!$D$2:$D$300,4)) | G14: =IF(B14="","",INDEX('ORR theo team'!$E$2:$E$300,4)/100) | H14: =IF(B14="","",INDEX('ORR theo team'!$F$2:$F$300,4)/100) | I14: =IF(B14="","",(H14-G14)*100) | J14: =IF(B14="","",INDEX('ORR theo team'!$G$2:$G$300,4)/100)
B15: =IF(INDEX('ORR theo team'!$A$2:$A$300,5)="","",INDEX('ORR theo team'!$A$2:$A$300,5)) | D15: =IF(B15="","",INDEX('ORR theo team'!$B$2:$B$300,5)/100) | E15: =IF(INDEX('ORR theo team'!$C$2:$C$300,5)="","",INDEX('ORR theo team'!$C$2:$C$300,5)) | F15: =IF(INDEX('ORR theo team'!$D$2:$D$300,5)="","",INDEX('ORR theo team'!$D$2:$D$300,5)) | G15: =IF(B15="","",INDEX('ORR theo team'!$E$2:$E$300,5)/100) | H15: =IF(B15="","",INDEX('ORR theo team'!$F$2:$F$300,5)/100) | I15: =IF(B15="","",(H15-G15)*100) | J15: =IF(B15="","",INDEX('ORR theo team'!$G$2:$G$300,5)/100)
B16: =IF(INDEX('ORR theo team'!$A$2:$A$300,6)="","",INDEX('ORR theo team'!$A$2:$A$300,6)) | D16: =IF(B16="","",INDEX('ORR theo team'!$B$2:$B$300,6)/100) | E16: =IF(INDEX('ORR theo team'!$C$2:$C$300,6)="","",INDEX('ORR theo team'!$C$2:$C$300,6)) | F16: =IF(INDEX('ORR theo team'!$D$2:$D$300,6)="","",INDEX('ORR theo team'!$D$2:$D$300,6)) | G16: =IF(B16="","",INDEX('ORR theo team'!$E$2:$E$300,6)/100) | H16: =IF(B16="","",INDEX('ORR theo team'!$F$2:$F$300,6)/100) | I16: =IF(B16="","",(H16-G16)*100) | J16: =IF(B16="","",INDEX('ORR theo team'!$G$2:$G$300,6)/100)
B17: =IF(INDEX('ORR theo team'!$A$2:$A$300,7)="","",INDEX('ORR theo team'!$A$2:$A$300,7)) | D17: =IF(B17="","",INDEX('ORR theo team'!$B$2:$B$300,7)/100) | E17: =IF(INDEX('ORR theo team'!$C$2:$C$300,7)="","",INDEX('ORR theo team'!$C$2:$C$300,7)) | F17: =IF(INDEX('ORR theo team'!$D$2:$D$300,7)="","",INDEX('ORR theo team'!$D$2:$D$300,7)) | G17: =IF(B17="","",INDEX('ORR theo team'!$E$2:$E$300,7)/100) | H17: =IF(B17="","",INDEX('ORR theo team'!$F$2:$F$300,7)/100) | I17: =IF(B17="","",(H17-G17)*100) | J17: =IF(B17="","",INDEX('ORR theo team'!$G$2:$G$300,7)/100)
B18: =IF(INDEX('ORR theo team'!$A$2:$A$300,8)="","",INDEX('ORR theo team'!$A$2:$A$300,8)) | D18: =IF(B18="","",INDEX('ORR theo team'!$B$2:$B$300,8)/100) | E18: =IF(INDEX('ORR theo team'!$C$2:$C$300,8)="","",INDEX('ORR theo team'!$C$2:$C$300,8)) | F18: =IF(INDEX('ORR theo team'!$D$2:$D$300,8)="","",INDEX('ORR theo team'!$D$2:$D$300,8)) | G18: =IF(B18="","",INDEX('ORR theo team'!$E$2:$E$300,8)/100) | H18: =IF(B18="","",INDEX('ORR theo team'!$F$2:$F$300,8)/100) | I18: =IF(B18="","",(H18-G18)*100) | J18: =IF(B18="","",INDEX('ORR theo team'!$G$2:$G$300,8)/100)
B19: =IF(INDEX('ORR theo team'!$A$2:$A$300,9)="","",INDEX('ORR theo team'!$A$2:$A$300,9)) | D19: =IF(B19="","",INDEX('ORR theo team'!$B$2:$B$300,9)/100) | E19: =IF(INDEX('ORR theo team'!$C$2:$C$300,9)="","",INDEX('ORR theo team'!$C$2:$C$300,9)) | F19: =IF(INDEX('ORR theo team'!$D$2:$D$300,9)="","",INDEX('ORR theo team'!$D$2:$D$300,9)) | G19: =IF(B19="","",INDEX('ORR theo team'!$E$2:$E$300,9)/100) | H19: =IF(B19="","",INDEX('ORR theo team'!$F$2:$F$300,9)/100) | I19: =IF(B19="","",(H19-G19)*100) | J19: =IF(B19="","",INDEX('ORR theo team'!$G$2:$G$300,9)/100)
B20: =IF(INDEX('ORR theo team'!$A$2:$A$300,10)="","",INDEX('ORR theo team'!$A$2:$A$300,10)) | D20: =IF(B20="","",INDEX('ORR theo team'!$B$2:$B$300,10)/100) | E20: =IF(INDEX('ORR theo team'!$C$2:$C$300,10)="","",INDEX('ORR theo team'!$C$2:$C$300,10)) | F20: =IF(INDEX('ORR theo team'!$D$2:$D$300,10)="","",INDEX('ORR theo team'!$D$2:$D$300,10)) | G20: =IF(B20="","",INDEX('ORR theo team'!$E$2:$E$300,10)/100) | H20: =IF(B20="","",INDEX('ORR theo team'!$F$2:$F$300,10)/100) | I20: =IF(B20="","",(H20-G20)*100) | J20: =IF(B20="","",INDEX('ORR theo team'!$G$2:$G$300,10)/100)
B21: =IF(INDEX('ORR theo team'!$A$2:$A$300,11)="","",INDEX('ORR theo team'!$A$2:$A$300,11)) | D21: =IF(B21="","",INDEX('ORR theo team'!$B$2:$B$300,11)/100) | E21: =IF(INDEX('ORR theo team'!$C$2:$C$300,11)="","",INDEX('ORR theo team'!$C$2:$C$300,11)) | F21: =IF(INDEX('ORR theo team'!$D$2:$D$300,11)="","",INDEX('ORR theo team'!$D$2:$D$300,11)) | G21: =IF(B21="","",INDEX('ORR theo team'!$E$2:$E$300,11)/100) | H21: =IF(B21="","",INDEX('ORR theo team'!$F$2:$F$300,11)/100) | I21: =IF(B21="","",(H21-G21)*100) | J21: =IF(B21="","",INDEX('ORR theo team'!$G$2:$G$300,11)/100)
B22: =IF(INDEX('ORR theo team'!$A$2:$A$300,12)="","",INDEX('ORR theo team'!$A$2:$A$300,12)) | D22: =IF(B22="","",INDEX('ORR theo team'!$B$2:$B$300,12)/100) | E22: =IF(INDEX('ORR theo team'!$C$2:$C$300,12)="","",INDEX('ORR theo team'!$C$2:$C$300,12)) | F22: =IF(INDEX('ORR theo team'!$D$2:$D$300,12)="","",INDEX('ORR theo team'!$D$2:$D$300,12)) | G22: =IF(B22="","",INDEX('ORR theo team'!$E$2:$E$300,12)/100) | H22: =IF(B22="","",INDEX('ORR theo team'!$F$2:$F$300,12)/100) | I22: =IF(B22="","",(H22-G22)*100) | J22: =IF(B22="","",INDEX('ORR theo team'!$G$2:$G$300,12)/100)
B25: Checklist by element (People · Plant · Process)
B26: Elements below 50% are shown in red.
B27: Code | C27: Element | H27: Group | I27: Items | J27: Progress
B28: =IF(INDEX('ORR hang muc'!$B$2:$B$300,1)="","",INDEX('ORR hang muc'!$B$2:$B$300,1)) | C28: =IF(INDEX('ORR hang muc'!$C$2:$C$300,1)="","",INDEX('ORR hang muc'!$C$2:$C$300,1)) | H28: =IF(INDEX('ORR hang muc'!$A$2:$A$300,1)="","",INDEX('ORR hang muc'!$A$2:$A$300,1)) | I28: =IF(INDEX('ORR hang muc'!$D$2:$D$300,1)="","",INDEX('ORR hang muc'!$D$2:$D$300,1)) | J28: =IF(B28="","",INDEX('ORR hang muc'!$E$2:$E$300,1)/100)
B29: =IF(INDEX('ORR hang muc'!$B$2:$B$300,2)="","",INDEX('ORR hang muc'!$B$2:$B$300,2)) | C29: =IF(INDEX('ORR hang muc'!$C$2:$C$300,2)="","",INDEX('ORR hang muc'!$C$2:$C$300,2)) | H29: =IF(INDEX('ORR hang muc'!$A$2:$A$300,2)="","",INDEX('ORR hang muc'!$A$2:$A$300,2)) | I29: =IF(INDEX('ORR hang muc'!$D$2:$D$300,2)="","",INDEX('ORR hang muc'!$D$2:$D$300,2)) | J29: =IF(B29="","",INDEX('ORR hang muc'!$E$2:$E$300,2)/100)
B30: =IF(INDEX('ORR hang muc'!$B$2:$B$300,3)="","",INDEX('ORR hang muc'!$B$2:$B$300,3)) | C30: =IF(INDEX('ORR hang muc'!$C$2:$C$300,3)="","",INDEX('ORR hang muc'!$C$2:$C$300,3)) | H30: =IF(INDEX('ORR hang muc'!$A$2:$A$300,3)="","",INDEX('ORR hang muc'!$A$2:$A$300,3)) | I30: =IF(INDEX('ORR hang muc'!$D$2:$D$300,3)="","",INDEX('ORR hang muc'!$D$2:$D$300,3)) | J30: =IF(B30="","",INDEX('ORR hang muc'!$E$2:$E$300,3)/100)
B31: =IF(INDEX('ORR hang muc'!$B$2:$B$300,4)="","",INDEX('ORR hang muc'!$B$2:$B$300,4)) | C31: =IF(INDEX('ORR hang muc'!$C$2:$C$300,4)="","",INDEX('ORR hang muc'!$C$2:$C$300,4)) | H31: =IF(INDEX('ORR hang muc'!$A$2:$A$300,4)="","",INDEX('ORR hang muc'!$A$2:$A$300,4)) | I31: =IF(INDEX('ORR hang muc'!$D$2:$D$300,4)="","",INDEX('ORR hang muc'!$D$2:$D$300,4)) | J31: =IF(B31="","",INDEX('ORR hang muc'!$E$2:$E$300,4)/100)
B32: =IF(INDEX('ORR hang muc'!$B$2:$B$300,5)="","",INDEX('ORR hang muc'!$B$2:$B$300,5)) | C32: =IF(INDEX('ORR hang muc'!$C$2:$C$300,5)="","",INDEX('ORR hang muc'!$C$2:$C$300,5)) | H32: =IF(INDEX('ORR hang muc'!$A$2:$A$300,5)="","",INDEX('ORR hang muc'!$A$2:$A$300,5)) | I32: =IF(INDEX('ORR hang muc'!$D$2:$D$300,5)="","",INDEX('ORR hang muc'!$D$2:$D$300,5)) | J32: =IF(B32="","",INDEX('ORR hang muc'!$E$2:$E$300,5)/100)
B33: =IF(INDEX('ORR hang muc'!$B$2:$B$300,6)="","",INDEX('ORR hang muc'!$B$2:$B$300,6)) | C33: =IF(INDEX('ORR hang muc'!$C$2:$C$300,6)="","",INDEX('ORR hang muc'!$C$2:$C$300,6)) | H33: =IF(INDEX('ORR hang muc'!$A$2:$A$300,6)="","",INDEX('ORR hang muc'!$A$2:$A$300,6)) | I33: =IF(INDEX('ORR hang muc'!$D$2:$D$300,6)="","",INDEX('ORR hang muc'!$D$2:$D$300,6)) | J33: =IF(B33="","",INDEX('ORR hang muc'!$E$2:$E$300,6)/100)
B34: =IF(INDEX('ORR hang muc'!$B$2:$B$300,7)="","",INDEX('ORR hang muc'!$B$2:$B$300,7)) | C34: =IF(INDEX('ORR hang muc'!$C$2:$C$300,7)="","",INDEX('ORR hang muc'!$C$2:$C$300,7)) | H34: =IF(INDEX('ORR hang muc'!$A$2:$A$300,7)="","",INDEX('ORR hang muc'!$A$2:$A$300,7)) | I34: =IF(INDEX('ORR hang muc'!$D$2:$D$300,7)="","",INDEX('ORR hang muc'!$D$2:$D$300,7)) | J34: =IF(B34="","",INDEX('ORR hang muc'!$E$2:$E$300,7)/100)
B35: =IF(INDEX('ORR hang muc'!$B$2:$B$300,8)="","",INDEX('ORR hang muc'!$B$2:$B$300,8)) | C35: =IF(INDEX('ORR hang muc'!$C$2:$C$300,8)="","",INDEX('ORR hang muc'!$C$2:$C$300,8)) | H35: =IF(INDEX('ORR hang muc'!$A$2:$A$300,8)="","",INDEX('ORR hang muc'!$A$2:$A$300,8)) | I35: =IF(INDEX('ORR hang muc'!$D$2:$D$300,8)="","",INDEX('ORR hang muc'!$D$2:$D$300,8)) | J35: =IF(B35="","",INDEX('ORR hang muc'!$E$2:$E$300,8)/100)
B36: =IF(INDEX('ORR hang muc'!$B$2:$B$300,9)="","",INDEX('ORR hang muc'!$B$2:$B$300,9)) | C36: =IF(INDEX('ORR hang muc'!$C$2:$C$300,9)="","",INDEX('ORR hang muc'!$C$2:$C$300,9)) | H36: =IF(INDEX('ORR hang muc'!$A$2:$A$300,9)="","",INDEX('ORR hang muc'!$A$2:$A$300,9)) | I36: =IF(INDEX('ORR hang muc'!$D$2:$D$300,9)="","",INDEX('ORR hang muc'!$D$2:$D$300,9)) | J36: =IF(B36="","",INDEX('ORR hang muc'!$E$2:$E$300,9)/100)
B37: =IF(INDEX('ORR hang muc'!$B$2:$B$300,10)="","",INDEX('ORR hang muc'!$B$2:$B$300,10)) | C37: =IF(INDEX('ORR hang muc'!$C$2:$C$300,10)="","",INDEX('ORR hang muc'!$C$2:$C$300,10)) | H37: =IF(INDEX('ORR hang muc'!$A$2:$A$300,10)="","",INDEX('ORR hang muc'!$A$2:$A$300,10)) | I37: =IF(INDEX('ORR hang muc'!$D$2:$D$300,10)="","",INDEX('ORR hang muc'!$D$2:$D$300,10)) | J37: =IF(B37="","",INDEX('ORR hang muc'!$E$2:$E$300,10)/100)
B38: =IF(INDEX('ORR hang muc'!$B$2:$B$300,11)="","",INDEX('ORR hang muc'!$B$2:$B$300,11)) | C38: =IF(INDEX('ORR hang muc'!$C$2:$C$300,11)="","",INDEX('ORR hang muc'!$C$2:$C$300,11)) | H38: =IF(INDEX('ORR hang muc'!$A$2:$A$300,11)="","",INDEX('ORR hang muc'!$A$2:$A$300,11)) | I38: =IF(INDEX('ORR hang muc'!$D$2:$D$300,11)="","",INDEX('ORR hang muc'!$D$2:$D$300,11)) | J38: =IF(B38="","",INDEX('ORR hang muc'!$E$2:$E$300,11)/100)
B39: =IF(INDEX('ORR hang muc'!$B$2:$B$300,12)="","",INDEX('ORR hang muc'!$B$2:$B$300,12)) | C39: =IF(INDEX('ORR hang muc'!$C$2:$C$300,12)="","",INDEX('ORR hang muc'!$C$2:$C$300,12)) | H39: =IF(INDEX('ORR hang muc'!$A$2:$A$300,12)="","",INDEX('ORR hang muc'!$A$2:$A$300,12)) | I39: =IF(INDEX('ORR hang muc'!$D$2:$D$300,12)="","",INDEX('ORR hang muc'!$D$2:$D$300,12)) | J39: =IF(B39="","",INDEX('ORR hang muc'!$E$2:$E$300,12)/100)
B40: =IF(INDEX('ORR hang muc'!$B$2:$B$300,13)="","",INDEX('ORR hang muc'!$B$2:$B$300,13)) | C40: =IF(INDEX('ORR hang muc'!$C$2:$C$300,13)="","",INDEX('ORR hang muc'!$C$2:$C$300,13)) | H40: =IF(INDEX('ORR hang muc'!$A$2:$A$300,13)="","",INDEX('ORR hang muc'!$A$2:$A$300,13)) | I40: =IF(INDEX('ORR hang muc'!$D$2:$D$300,13)="","",INDEX('ORR hang muc'!$D$2:$D$300,13)) | J40: =IF(B40="","",INDEX('ORR hang muc'!$E$2:$E$300,13)/100)
B41: =IF(INDEX('ORR hang muc'!$B$2:$B$300,14)="","",INDEX('ORR hang muc'!$B$2:$B$300,14)) | C41: =IF(INDEX('ORR hang muc'!$C$2:$C$300,14)="","",INDEX('ORR hang muc'!$C$2:$C$300,14)) | H41: =IF(INDEX('ORR hang muc'!$A$2:$A$300,14)="","",INDEX('ORR hang muc'!$A$2:$A$300,14)) | I41: =IF(INDEX('ORR hang muc'!$D$2:$D$300,14)="","",INDEX('ORR hang muc'!$D$2:$D$300,14)) | J41: =IF(B41="","",INDEX('ORR hang muc'!$E$2:$E$300,14)/100)
B42: =IF(INDEX('ORR hang muc'!$B$2:$B$300,15)="","",INDEX('ORR hang muc'!$B$2:$B$300,15)) | C42: =IF(INDEX('ORR hang muc'!$C$2:$C$300,15)="","",INDEX('ORR hang muc'!$C$2:$C$300,15)) | H42: =IF(INDEX('ORR hang muc'!$A$2:$A$300,15)="","",INDEX('ORR hang muc'!$A$2:$A$300,15)) | I42: =IF(INDEX('ORR hang muc'!$D$2:$D$300,15)="","",INDEX('ORR hang muc'!$D$2:$D$300,15)) | J42: =IF(B42="","",INDEX('ORR hang muc'!$E$2:$E$300,15)/100)
B43: =IF(INDEX('ORR hang muc'!$B$2:$B$300,16)="","",INDEX('ORR hang muc'!$B$2:$B$300,16)) | C43: =IF(INDEX('ORR hang muc'!$C$2:$C$300,16)="","",INDEX('ORR hang muc'!$C$2:$C$300,16)) | H43: =IF(INDEX('ORR hang muc'!$A$2:$A$300,16)="","",INDEX('ORR hang muc'!$A$2:$A$300,16)) | I43: =IF(INDEX('ORR hang muc'!$D$2:$D$300,16)="","",INDEX('ORR hang muc'!$D$2:$D$300,16)) | J43: =IF(B43="","",INDEX('ORR hang muc'!$E$2:$E$300,16)/100)
B44: =IF(INDEX('ORR hang muc'!$B$2:$B$300,17)="","",INDEX('ORR hang muc'!$B$2:$B$300,17)) | C44: =IF(INDEX('ORR hang muc'!$C$2:$C$300,17)="","",INDEX('ORR hang muc'!$C$2:$C$300,17)) | H44: =IF(INDEX('ORR hang muc'!$A$2:$A$300,17)="","",INDEX('ORR hang muc'!$A$2:$A$300,17)) | I44: =IF(INDEX('ORR hang muc'!$D$2:$D$300,17)="","",INDEX('ORR hang muc'!$D$2:$D$300,17)) | J44: =IF(B44="","",INDEX('ORR hang muc'!$E$2:$E$300,17)/100)
B45: =IF(INDEX('ORR hang muc'!$B$2:$B$300,18)="","",INDEX('ORR hang muc'!$B$2:$B$300,18)) | C45: =IF(INDEX('ORR hang muc'!$C$2:$C$300,18)="","",INDEX('ORR hang muc'!$C$2:$C$300,18)) | H45: =IF(INDEX('ORR hang muc'!$A$2:$A$300,18)="","",INDEX('ORR hang muc'!$A$2:$A$300,18)) | I45: =IF(INDEX('ORR hang muc'!$D$2:$D$300,18)="","",INDEX('ORR hang muc'!$D$2:$D$300,18)) | J45: =IF(B45="","",INDEX('ORR hang muc'!$E$2:$E$300,18)/100)
...

Sheet Procedures
B1: ="OPS readiness – report "&TEXT(DATEVALUE('Thong tin'!$A$2),"d mmm yyyy")
B2: Procedure completion. The full register is the "Quy trinh" data sheet; this page lists the ones still open.
B4: ="HSE procedures · "&COUNTIFS('Quy trinh'!$B$2:$B$300,"HSE")&" documents" | G4: ="General operations procedures · "&COUNTIFS('Quy trinh'!$B$2:$B$300,"General operations")&" documents"
B5: =AVERAGEIFS('Quy trinh'!$H$2:$H$300,'Quy trinh'!$B$2:$B$300,"HSE")/100 | G5: =AVERAGEIFS('Quy trinh'!$H$2:$H$300,'Quy trinh'!$B$2:$B$300,"General operations")/100
B6: =COUNTIFS('Quy trinh'!$B$2:$B$300,"HSE",'Quy trinh'!$E$2:$E$300,"<>Yes")&" not yet issued" | G6: =COUNTIFS('Quy trinh'!$B$2:$B$300,"General operations",'Quy trinh'!$E$2:$E$300,"<>Yes")&" not yet issued"
B8: Open procedures (not yet issued)
B9: In register order. Red: 0% · amber: in progress.
B10: Code | C10: Document | G10: Owner | I10: Due | J10: Completion | K10: Remark
B11: =IF($Z11="","",IF(INDEX('Quy trinh'!$A$2:$A$300,$Z11)="","",INDEX('Quy trinh'!$A$2:$A$300,$Z11))) | C11: =IF($Z11="","",IF(INDEX('Quy trinh'!$C$2:$C$300,$Z11)="","",INDEX('Quy trinh'!$C$2:$C$300,$Z11))) | G11: =IF($Z11="","",IF(INDEX('Quy trinh'!$F$2:$F$300,$Z11)="","",INDEX('Quy trinh'!$F$2:$F$300,$Z11))) | I11: =IF($Z11="","",IF(INDEX('Quy trinh'!$G$2:$G$300,$Z11)="","",INDEX('Quy trinh'!$G$2:$G$300,$Z11))) | J11: =IF($Z11="","",INDEX('Quy trinh'!$H$2:$H$300,$Z11)/100) | K11: =IF($Z11="","",IF(INDEX('Quy trinh'!$I$2:$I$300,$Z11)="","",INDEX('Quy trinh'!$I$2:$I$300,$Z11))) | Z11: {=IFERROR(SMALL(IF(('Quy trinh'!$E$2:$E$300<>"Yes")*('Quy trinh'!$C$2:$C$300<>""),ROW('Quy trinh'!$A$2:$A$300)-1),1),"")}
B12: =IF($Z12="","",IF(INDEX('Quy trinh'!$A$2:$A$300,$Z12)="","",INDEX('Quy trinh'!$A$2:$A$300,$Z12))) | C12: =IF($Z12="","",IF(INDEX('Quy trinh'!$C$2:$C$300,$Z12)="","",INDEX('Quy trinh'!$C$2:$C$300,$Z12))) | G12: =IF($Z12="","",IF(INDEX('Quy trinh'!$F$2:$F$300,$Z12)="","",INDEX('Quy trinh'!$F$2:$F$300,$Z12))) | I12: =IF($Z12="","",IF(INDEX('Quy trinh'!$G$2:$G$300,$Z12)="","",INDEX('Quy trinh'!$G$2:$G$300,$Z12))) | J12: =IF($Z12="","",INDEX('Quy trinh'!$H$2:$H$300,$Z12)/100) | K12: =IF($Z12="","",IF(INDEX('Quy trinh'!$I$2:$I$300,$Z12)="","",INDEX('Quy trinh'!$I$2:$I$300,$Z12))) | Z12: {=IFERROR(SMALL(IF(('Quy trinh'!$E$2:$E$300<>"Yes")*('Quy trinh'!$C$2:$C$300<>""),ROW('Quy trinh'!$A$2:$A$300)-1),2),"")}
B13: =IF($Z13="","",IF(INDEX('Quy trinh'!$A$2:$A$300,$Z13)="","",INDEX('Quy trinh'!$A$2:$A$300,$Z13))) | C13: =IF($Z13="","",IF(INDEX('Quy trinh'!$C$2:$C$300,$Z13)="","",INDEX('Quy trinh'!$C$2:$C$300,$Z13))) | G13: =IF($Z13="","",IF(INDEX('Quy trinh'!$F$2:$F$300,$Z13)="","",INDEX('Quy trinh'!$F$2:$F$300,$Z13))) | I13: =IF($Z13="","",IF(INDEX('Quy trinh'!$G$2:$G$300,$Z13)="","",INDEX('Quy trinh'!$G$2:$G$300,$Z13))) | J13: =IF($Z13="","",INDEX('Quy trinh'!$H$2:$H$300,$Z13)/100) | K13: =IF($Z13="","",IF(INDEX('Quy trinh'!$I$2:$I$300,$Z13)="","",INDEX('Quy trinh'!$I$2:$I$300,$Z13))) | Z13: {=IFERROR(SMALL(IF(('Quy trinh'!$E$2:$E$300<>"Yes")*('Quy trinh'!$C$2:$C$300<>""),ROW('Quy trinh'!$A$2:$A$300)-1),3),"")}
B14: =IF($Z14="","",IF(INDEX('Quy trinh'!$A$2:$A$300,$Z14)="","",INDEX('Quy trinh'!$A$2:$A$300,$Z14))) | C14: =IF($Z14="","",IF(INDEX('Quy trinh'!$C$2:$C$300,$Z14)="","",INDEX('Quy trinh'!$C$2:$C$300,$Z14))) | G14: =IF($Z14="","",IF(INDEX('Quy trinh'!$F$2:$F$300,$Z14)="","",INDEX('Quy trinh'!$F$2:$F$300,$Z14))) | I14: =IF($Z14="","",IF(INDEX('Quy trinh'!$G$2:$G$300,$Z14)="","",INDEX('Quy trinh'!$G$2:$G$300,$Z14))) | J14: =IF($Z14="","",INDEX('Quy trinh'!$H$2:$H$300,$Z14)/100) | K14: =IF($Z14="","",IF(INDEX('Quy trinh'!$I$2:$I$300,$Z14)="","",INDEX('Quy trinh'!$I$2:$I$300,$Z14))) | Z14: {=IFERROR(SMALL(IF(('Quy trinh'!$E$2:$E$300<>"Yes")*('Quy trinh'!$C$2:$C$300<>""),ROW('Quy trinh'!$A$2:$A$300)-1),4),"")}
B15: =IF($Z15="","",IF(INDEX('Quy trinh'!$A$2:$A$300,$Z15)="","",INDEX('Quy trinh'!$A$2:$A$300,$Z15))) | C15: =IF($Z15="","",IF(INDEX('Quy trinh'!$C$2:$C$300,$Z15)="","",INDEX('Quy trinh'!$C$2:$C$300,$Z15))) | G15: =IF($Z15="","",IF(INDEX('Quy trinh'!$F$2:$F$300,$Z15)="","",INDEX('Quy trinh'!$F$2:$F$300,$Z15))) | I15: =IF($Z15="","",IF(INDEX('Quy trinh'!$G$2:$G$300,$Z15)="","",INDEX('Quy trinh'!$G$2:$G$300,$Z15))) | J15: =IF($Z15="","",INDEX('Quy trinh'!$H$2:$H$300,$Z15)/100) | K15: =IF($Z15="","",IF(INDEX('Quy trinh'!$I$2:$I$300,$Z15)="","",INDEX('Quy trinh'!$I$2:$I$300,$Z15))) | Z15: {=IFERROR(SMALL(IF(('Quy trinh'!$E$2:$E$300<>"Yes")*('Quy trinh'!$C$2:$C$300<>""),ROW('Quy trinh'!$A$2:$A$300)-1),5),"")}
B16: =IF($Z16="","",IF(INDEX('Quy trinh'!$A$2:$A$300,$Z16)="","",INDEX('Quy trinh'!$A$2:$A$300,$Z16))) | C16: =IF($Z16="","",IF(INDEX('Quy trinh'!$C$2:$C$300,$Z16)="","",INDEX('Quy trinh'!$C$2:$C$300,$Z16))) | G16: =IF($Z16="","",IF(INDEX('Quy trinh'!$F$2:$F$300,$Z16)="","",INDEX('Quy trinh'!$F$2:$F$300,$Z16))) | I16: =IF($Z16="","",IF(INDEX('Quy trinh'!$G$2:$G$300,$Z16)="","",INDEX('Quy trinh'!$G$2:$G$300,$Z16))) | J16: =IF($Z16="","",INDEX('Quy trinh'!$H$2:$H$300,$Z16)/100) | K16: =IF($Z16="","",IF(INDEX('Quy trinh'!$I$2:$I$300,$Z16)="","",INDEX('Quy trinh'!$I$2:$I$300,$Z16))) | Z16: {=IFERROR(SMALL(IF(('Quy trinh'!$E$2:$E$300<>"Yes")*('Quy trinh'!$C$2:$C$300<>""),ROW('Quy trinh'!$A$2:$A$300)-1),6),"")}
B17: =IF($Z17="","",IF(INDEX('Quy trinh'!$A$2:$A$300,$Z17)="","",INDEX('Quy trinh'!$A$2:$A$300,$Z17))) | C17: =IF($Z17="","",IF(INDEX('Quy trinh'!$C$2:$C$300,$Z17)="","",INDEX('Quy trinh'!$C$2:$C$300,$Z17))) | G17: =IF($Z17="","",IF(INDEX('Quy trinh'!$F$2:$F$300,$Z17)="","",INDEX('Quy trinh'!$F$2:$F$300,$Z17))) | I17: =IF($Z17="","",IF(INDEX('Quy trinh'!$G$2:$G$300,$Z17)="","",INDEX('Quy trinh'!$G$2:$G$300,$Z17))) | J17: =IF($Z17="","",INDEX('Quy trinh'!$H$2:$H$300,$Z17)/100) | K17: =IF($Z17="","",IF(INDEX('Quy trinh'!$I$2:$I$300,$Z17)="","",INDEX('Quy trinh'!$I$2:$I$300,$Z17))) | Z17: {=IFERROR(SMALL(IF(('Quy trinh'!$E$2:$E$300<>"Yes")*('Quy trinh'!$C$2:$C$300<>""),ROW('Quy trinh'!$A$2:$A$300)-1),7),"")}
B18: =IF($Z18="","",IF(INDEX('Quy trinh'!$A$2:$A$300,$Z18)="","",INDEX('Quy trinh'!$A$2:$A$300,$Z18))) | C18: =IF($Z18="","",IF(INDEX('Quy trinh'!$C$2:$C$300,$Z18)="","",INDEX('Quy trinh'!$C$2:$C$300,$Z18))) | G18: =IF($Z18="","",IF(INDEX('Quy trinh'!$F$2:$F$300,$Z18)="","",INDEX('Quy trinh'!$F$2:$F$300,$Z18))) | I18: =IF($Z18="","",IF(INDEX('Quy trinh'!$G$2:$G$300,$Z18)="","",INDEX('Quy trinh'!$G$2:$G$300,$Z18))) | J18: =IF($Z18="","",INDEX('Quy trinh'!$H$2:$H$300,$Z18)/100) | K18: =IF($Z18="","",IF(INDEX('Quy trinh'!$I$2:$I$300,$Z18)="","",INDEX('Quy trinh'!$I$2:$I$300,$Z18))) | Z18: {=IFERROR(SMALL(IF(('Quy trinh'!$E$2:$E$300<>"Yes")*('Quy trinh'!$C$2:$C$300<>""),ROW('Quy trinh'!$A$2:$A$300)-1),8),"")}
B19: =IF($Z19="","",IF(INDEX('Quy trinh'!$A$2:$A$300,$Z19)="","",INDEX('Quy trinh'!$A$2:$A$300,$Z19))) | C19: =IF($Z19="","",IF(INDEX('Quy trinh'!$C$2:$C$300,$Z19)="","",INDEX('Quy trinh'!$C$2:$C$300,$Z19))) | G19: =IF($Z19="","",IF(INDEX('Quy trinh'!$F$2:$F$300,$Z19)="","",INDEX('Quy trinh'!$F$2:$F$300,$Z19))) | I19: =IF($Z19="","",IF(INDEX('Quy trinh'!$G$2:$G$300,$Z19)="","",INDEX('Quy trinh'!$G$2:$G$300,$Z19))) | J19: =IF($Z19="","",INDEX('Quy trinh'!$H$2:$H$300,$Z19)/100) | K19: =IF($Z19="","",IF(INDEX('Quy trinh'!$I$2:$I$300,$Z19)="","",INDEX('Quy trinh'!$I$2:$I$300,$Z19))) | Z19: {=IFERROR(SMALL(IF(('Quy trinh'!$E$2:$E$300<>"Yes")*('Quy trinh'!$C$2:$C$300<>""),ROW('Quy trinh'!$A$2:$A$300)-1),9),"")}
B20: =IF($Z20="","",IF(INDEX('Quy trinh'!$A$2:$A$300,$Z20)="","",INDEX('Quy trinh'!$A$2:$A$300,$Z20))) | C20: =IF($Z20="","",IF(INDEX('Quy trinh'!$C$2:$C$300,$Z20)="","",INDEX('Quy trinh'!$C$2:$C$300,$Z20))) | G20: =IF($Z20="","",IF(INDEX('Quy trinh'!$F$2:$F$300,$Z20)="","",INDEX('Quy trinh'!$F$2:$F$300,$Z20))) | I20: =IF($Z20="","",IF(INDEX('Quy trinh'!$G$2:$G$300,$Z20)="","",INDEX('Quy trinh'!$G$2:$G$300,$Z20))) | J20: =IF($Z20="","",INDEX('Quy trinh'!$H$2:$H$300,$Z20)/100) | K20: =IF($Z20="","",IF(INDEX('Quy trinh'!$I$2:$I$300,$Z20)="","",INDEX('Quy trinh'!$I$2:$I$300,$Z20))) | Z20: {=IFERROR(SMALL(IF(('Quy trinh'!$E$2:$E$300<>"Yes")*('Quy trinh'!$C$2:$C$300<>""),ROW('Quy trinh'!$A$2:$A$300)-1),10),"")}
B21: =IF($Z21="","",IF(INDEX('Quy trinh'!$A$2:$A$300,$Z21)="","",INDEX('Quy trinh'!$A$2:$A$300,$Z21))) | C21: =IF($Z21="","",IF(INDEX('Quy trinh'!$C$2:$C$300,$Z21)="","",INDEX('Quy trinh'!$C$2:$C$300,$Z21))) | G21: =IF($Z21="","",IF(INDEX('Quy trinh'!$F$2:$F$300,$Z21)="","",INDEX('Quy trinh'!$F$2:$F$300,$Z21))) | I21: =IF($Z21="","",IF(INDEX('Quy trinh'!$G$2:$G$300,$Z21)="","",INDEX('Quy trinh'!$G$2:$G$300,$Z21))) | J21: =IF($Z21="","",INDEX('Quy trinh'!$H$2:$H$300,$Z21)/100) | K21: =IF($Z21="","",IF(INDEX('Quy trinh'!$I$2:$I$300,$Z21)="","",INDEX('Quy trinh'!$I$2:$I$300,$Z21))) | Z21: {=IFERROR(SMALL(IF(('Quy trinh'!$E$2:$E$300<>"Yes")*('Quy trinh'!$C$2:$C$300<>""),ROW('Quy trinh'!$A$2:$A$300)-1),11),"")}
B22: =IF($Z22="","",IF(INDEX('Quy trinh'!$A$2:$A$300,$Z22)="","",INDEX('Quy trinh'!$A$2:$A$300,$Z22))) | C22: =IF($Z22="","",IF(INDEX('Quy trinh'!$C$2:$C$300,$Z22)="","",INDEX('Quy trinh'!$C$2:$C$300,$Z22))) | G22: =IF($Z22="","",IF(INDEX('Quy trinh'!$F$2:$F$300,$Z22)="","",INDEX('Quy trinh'!$F$2:$F$300,$Z22))) | I22: =IF($Z22="","",IF(INDEX('Quy trinh'!$G$2:$G$300,$Z22)="","",INDEX('Quy trinh'!$G$2:$G$300,$Z22))) | J22: =IF($Z22="","",INDEX('Quy trinh'!$H$2:$H$300,$Z22)/100) | K22: =IF($Z22="","",IF(INDEX('Quy trinh'!$I$2:$I$300,$Z22)="","",INDEX('Quy trinh'!$I$2:$I$300,$Z22))) | Z22: {=IFERROR(SMALL(IF(('Quy trinh'!$E$2:$E$300<>"Yes")*('Quy trinh'!$C$2:$C$300<>""),ROW('Quy trinh'!$A$2:$A$300)-1),12),"")}
B23: =IF($Z23="","",IF(INDEX('Quy trinh'!$A$2:$A$300,$Z23)="","",INDEX('Quy trinh'!$A$2:$A$300,$Z23))) | C23: =IF($Z23="","",IF(INDEX('Quy trinh'!$C$2:$C$300,$Z23)="","",INDEX('Quy trinh'!$C$2:$C$300,$Z23))) | G23: =IF($Z23="","",IF(INDEX('Quy trinh'!$F$2:$F$300,$Z23)="","",INDEX('Quy trinh'!$F$2:$F$300,$Z23))) | I23: =IF($Z23="","",IF(INDEX('Quy trinh'!$G$2:$G$300,$Z23)="","",INDEX('Quy trinh'!$G$2:$G$300,$Z23))) | J23: =IF($Z23="","",INDEX('Quy trinh'!$H$2:$H$300,$Z23)/100) | K23: =IF($Z23="","",IF(INDEX('Quy trinh'!$I$2:$I$300,$Z23)="","",INDEX('Quy trinh'!$I$2:$I$300,$Z23))) | Z23: {=IFERROR(SMALL(IF(('Quy trinh'!$E$2:$E$300<>"Yes")*('Quy trinh'!$C$2:$C$300<>""),ROW('Quy trinh'!$A$2:$A$300)-1),13),"")}
B24: =IF($Z24="","",IF(INDEX('Quy trinh'!$A$2:$A$300,$Z24)="","",INDEX('Quy trinh'!$A$2:$A$300,$Z24))) | C24: =IF($Z24="","",IF(INDEX('Quy trinh'!$C$2:$C$300,$Z24)="","",INDEX('Quy trinh'!$C$2:$C$300,$Z24))) | G24: =IF($Z24="","",IF(INDEX('Quy trinh'!$F$2:$F$300,$Z24)="","",INDEX('Quy trinh'!$F$2:$F$300,$Z24))) | I24: =IF($Z24="","",IF(INDEX('Quy trinh'!$G$2:$G$300,$Z24)="","",INDEX('Quy trinh'!$G$2:$G$300,$Z24))) | J24: =IF($Z24="","",INDEX('Quy trinh'!$H$2:$H$300,$Z24)/100) | K24: =IF($Z24="","",IF(INDEX('Quy trinh'!$I$2:$I$300,$Z24)="","",INDEX('Quy trinh'!$I$2:$I$300,$Z24))) | Z24: {=IFERROR(SMALL(IF(('Quy trinh'!$E$2:$E$300<>"Yes")*('Quy trinh'!$C$2:$C$300<>""),ROW('Quy trinh'!$A$2:$A$300)-1),14),"")}
B25: =IF($Z25="","",IF(INDEX('Quy trinh'!$A$2:$A$300,$Z25)="","",INDEX('Quy trinh'!$A$2:$A$300,$Z25))) | C25: =IF($Z25="","",IF(INDEX('Quy trinh'!$C$2:$C$300,$Z25)="","",INDEX('Quy trinh'!$C$2:$C$300,$Z25))) | G25: =IF($Z25="","",IF(INDEX('Quy trinh'!$F$2:$F$300,$Z25)="","",INDEX('Quy trinh'!$F$2:$F$300,$Z25))) | I25: =IF($Z25="","",IF(INDEX('Quy trinh'!$G$2:$G$300,$Z25)="","",INDEX('Quy trinh'!$G$2:$G$300,$Z25))) | J25: =IF($Z25="","",INDEX('Quy trinh'!$H$2:$H$300,$Z25)/100) | K25: =IF($Z25="","",IF(INDEX('Quy trinh'!$I$2:$I$300,$Z25)="","",INDEX('Quy trinh'!$I$2:$I$300,$Z25))) | Z25: {=IFERROR(SMALL(IF(('Quy trinh'!$E$2:$E$300<>"Yes")*('Quy trinh'!$C$2:$C$300<>""),ROW('Quy trinh'!$A$2:$A$300)-1),15),"")}
B26: =IF($Z26="","",IF(INDEX('Quy trinh'!$A$2:$A$300,$Z26)="","",INDEX('Quy trinh'!$A$2:$A$300,$Z26))) | C26: =IF($Z26="","",IF(INDEX('Quy trinh'!$C$2:$C$300,$Z26)="","",INDEX('Quy trinh'!$C$2:$C$300,$Z26))) | G26: =IF($Z26="","",IF(INDEX('Quy trinh'!$F$2:$F$300,$Z26)="","",INDEX('Quy trinh'!$F$2:$F$300,$Z26))) | I26: =IF($Z26="","",IF(INDEX('Quy trinh'!$G$2:$G$300,$Z26)="","",INDEX('Quy trinh'!$G$2:$G$300,$Z26))) | J26: =IF($Z26="","",INDEX('Quy trinh'!$H$2:$H$300,$Z26)/100) | K26: =IF($Z26="","",IF(INDEX('Quy trinh'!$I$2:$I$300,$Z26)="","",INDEX('Quy trinh'!$I$2:$I$300,$Z26))) | Z26: {=IFERROR(SMALL(IF(('Quy trinh'!$E$2:$E$300<>"Yes")*('Quy trinh'!$C$2:$C$300<>""),ROW('Quy trinh'!$A$2:$A$300)-1),16),"")}
B27: =IF($Z27="","",IF(INDEX('Quy trinh'!$A$2:$A$300,$Z27)="","",INDEX('Quy trinh'!$A$2:$A$300,$Z27))) | C27: =IF($Z27="","",IF(INDEX('Quy trinh'!$C$2:$C$300,$Z27)="","",INDEX('Quy trinh'!$C$2:$C$300,$Z27))) | G27: =IF($Z27="","",IF(INDEX('Quy trinh'!$F$2:$F$300,$Z27)="","",INDEX('Quy trinh'!$F$2:$F$300,$Z27))) | I27: =IF($Z27="","",IF(INDEX('Quy trinh'!$G$2:$G$300,$Z27)="","",INDEX('Quy trinh'!$G$2:$G$300,$Z27))) | J27: =IF($Z27="","",INDEX('Quy trinh'!$H$2:$H$300,$Z27)/100) | K27: =IF($Z27="","",IF(INDEX('Quy trinh'!$I$2:$I$300,$Z27)="","",INDEX('Quy trinh'!$I$2:$I$300,$Z27))) | Z27: {=IFERROR(SMALL(IF(('Quy trinh'!$E$2:$E$300<>"Yes")*('Quy trinh'!$C$2:$C$300<>""),ROW('Quy trinh'!$A$2:$A$300)-1),17),"")}
B28: =IF($Z28="","",IF(INDEX('Quy trinh'!$A$2:$A$300,$Z28)="","",INDEX('Quy trinh'!$A$2:$A$300,$Z28))) | C28: =IF($Z28="","",IF(INDEX('Quy trinh'!$C$2:$C$300,$Z28)="","",INDEX('Quy trinh'!$C$2:$C$300,$Z28))) | G28: =IF($Z28="","",IF(INDEX('Quy trinh'!$F$2:$F$300,$Z28)="","",INDEX('Quy trinh'!$F$2:$F$300,$Z28))) | I28: =IF($Z28="","",IF(INDEX('Quy trinh'!$G$2:$G$300,$Z28)="","",INDEX('Quy trinh'!$G$2:$G$300,$Z28))) | J28: =IF($Z28="","",INDEX('Quy trinh'!$H$2:$H$300,$Z28)/100) | K28: =IF($Z28="","",IF(INDEX('Quy trinh'!$I$2:$I$300,$Z28)="","",INDEX('Quy trinh'!$I$2:$I$300,$Z28))) | Z28: {=IFERROR(SMALL(IF(('Quy trinh'!$E$2:$E$300<>"Yes")*('Quy trinh'!$C$2:$C$300<>""),ROW('Quy trinh'!$A$2:$A$300)-1),18),"")}
B29: =IF($Z29="","",IF(INDEX('Quy trinh'!$A$2:$A$300,$Z29)="","",INDEX('Quy trinh'!$A$2:$A$300,$Z29))) | C29: =IF($Z29="","",IF(INDEX('Quy trinh'!$C$2:$C$300,$Z29)="","",INDEX('Quy trinh'!$C$2:$C$300,$Z29))) | G29: =IF($Z29="","",IF(INDEX('Quy trinh'!$F$2:$F$300,$Z29)="","",INDEX('Quy trinh'!$F$2:$F$300,$Z29))) | I29: =IF($Z29="","",IF(INDEX('Quy trinh'!$G$2:$G$300,$Z29)="","",INDEX('Quy trinh'!$G$2:$G$300,$Z29))) | J29: =IF($Z29="","",INDEX('Quy trinh'!$H$2:$H$300,$Z29)/100) | K29: =IF($Z29="","",IF(INDEX('Quy trinh'!$I$2:$I$300,$Z29)="","",INDEX('Quy trinh'!$I$2:$I$300,$Z29))) | Z29: {=IFERROR(SMALL(IF(('Quy trinh'!$E$2:$E$300<>"Yes")*('Quy trinh'!$C$2:$C$300<>""),ROW('Quy trinh'!$A$2:$A$300)-1),19),"")}
B30: =IF($Z30="","",IF(INDEX('Quy trinh'!$A$2:$A$300,$Z30)="","",INDEX('Quy trinh'!$A$2:$A$300,$Z30))) | C30: =IF($Z30="","",IF(INDEX('Quy trinh'!$C$2:$C$300,$Z30)="","",INDEX('Quy trinh'!$C$2:$C$300,$Z30))) | G30: =IF($Z30="","",IF(INDEX('Quy trinh'!$F$2:$F$300,$Z30)="","",INDEX('Quy trinh'!$F$2:$F$300,$Z30))) | I30: =IF($Z30="","",IF(INDEX('Quy trinh'!$G$2:$G$300,$Z30)="","",INDEX('Quy trinh'!$G$2:$G$300,$Z30))) | J30: =IF($Z30="","",INDEX('Quy trinh'!$H$2:$H$300,$Z30)/100) | K30: =IF($Z30="","",IF(INDEX('Quy trinh'!$I$2:$I$300,$Z30)="","",INDEX('Quy trinh'!$I$2:$I$300,$Z30))) | Z30: {=IFERROR(SMALL(IF(('Quy trinh'!$E$2:$E$300<>"Yes")*('Quy trinh'!$C$2:$C$300<>""),ROW('Quy trinh'!$A$2:$A$300)-1),20),"")}
B31: =IF($Z31="","",IF(INDEX('Quy trinh'!$A$2:$A$300,$Z31)="","",INDEX('Quy trinh'!$A$2:$A$300,$Z31))) | C31: =IF($Z31="","",IF(INDEX('Quy trinh'!$C$2:$C$300,$Z31)="","",INDEX('Quy trinh'!$C$2:$C$300,$Z31))) | G31: =IF($Z31="","",IF(INDEX('Quy trinh'!$F$2:$F$300,$Z31)="","",INDEX('Quy trinh'!$F$2:$F$300,$Z31))) | I31: =IF($Z31="","",IF(INDEX('Quy trinh'!$G$2:$G$300,$Z31)="","",INDEX('Quy trinh'!$G$2:$G$300,$Z31))) | J31: =IF($Z31="","",INDEX('Quy trinh'!$H$2:$H$300,$Z31)/100) | K31: =IF($Z31="","",IF(INDEX('Quy trinh'!$I$2:$I$300,$Z31)="","",INDEX('Quy trinh'!$I$2:$I$300,$Z31))) | Z31: {=IFERROR(SMALL(IF(('Quy trinh'!$E$2:$E$300<>"Yes")*('Quy trinh'!$C$2:$C$300<>""),ROW('Quy trinh'!$A$2:$A$300)-1),21),"")}
B32: =IF($Z32="","",IF(INDEX('Quy trinh'!$A$2:$A$300,$Z32)="","",INDEX('Quy trinh'!$A$2:$A$300,$Z32))) | C32: =IF($Z32="","",IF(INDEX('Quy trinh'!$C$2:$C$300,$Z32)="","",INDEX('Quy trinh'!$C$2:$C$300,$Z32))) | G32: =IF($Z32="","",IF(INDEX('Quy trinh'!$F$2:$F$300,$Z32)="","",INDEX('Quy trinh'!$F$2:$F$300,$Z32))) | I32: =IF($Z32="","",IF(INDEX('Quy trinh'!$G$2:$G$300,$Z32)="","",INDEX('Quy trinh'!$G$2:$G$300,$Z32))) | J32: =IF($Z32="","",INDEX('Quy trinh'!$H$2:$H$300,$Z32)/100) | K32: =IF($Z32="","",IF(INDEX('Quy trinh'!$I$2:$I$300,$Z32)="","",INDEX('Quy trinh'!$I$2:$I$300,$Z32))) | Z32: {=IFERROR(SMALL(IF(('Quy trinh'!$E$2:$E$300<>"Yes")*('Quy trinh'!$C$2:$C$300<>""),ROW('Quy trinh'!$A$2:$A$300)-1),22),"")}
B33: =IF($Z33="","",IF(INDEX('Quy trinh'!$A$2:$A$300,$Z33)="","",INDEX('Quy trinh'!$A$2:$A$300,$Z33))) | C33: =IF($Z33="","",IF(INDEX('Quy trinh'!$C$2:$C$300,$Z33)="","",INDEX('Quy trinh'!$C$2:$C$300,$Z33))) | G33: =IF($Z33="","",IF(INDEX('Quy trinh'!$F$2:$F$300,$Z33)="","",INDEX('Quy trinh'!$F$2:$F$300,$Z33))) | I33: =IF($Z33="","",IF(INDEX('Quy trinh'!$G$2:$G$300,$Z33)="","",INDEX('Quy trinh'!$G$2:$G$300,$Z33))) | J33: =IF($Z33="","",INDEX('Quy trinh'!$H$2:$H$300,$Z33)/100) | K33: =IF($Z33="","",IF(INDEX('Quy trinh'!$I$2:$I$300,$Z33)="","",INDEX('Quy trinh'!$I$2:$I$300,$Z33))) | Z33: {=IFERROR(SMALL(IF(('Quy trinh'!$E$2:$E$300<>"Yes")*('Quy trinh'!$C$2:$C$300<>""),ROW('Quy trinh'!$A$2:$A$300)-1),23),"")}
B34: =IF($Z34="","",IF(INDEX('Quy trinh'!$A$2:$A$300,$Z34)="","",INDEX('Quy trinh'!$A$2:$A$300,$Z34))) | C34: =IF($Z34="","",IF(INDEX('Quy trinh'!$C$2:$C$300,$Z34)="","",INDEX('Quy trinh'!$C$2:$C$300,$Z34))) | G34: =IF($Z34="","",IF(INDEX('Quy trinh'!$F$2:$F$300,$Z34)="","",INDEX('Quy trinh'!$F$2:$F$300,$Z34))) | I34: =IF($Z34="","",IF(INDEX('Quy trinh'!$G$2:$G$300,$Z34)="","",INDEX('Quy trinh'!$G$2:$G$300,$Z34))) | J34: =IF($Z34="","",INDEX('Quy trinh'!$H$2:$H$300,$Z34)/100) | K34: =IF($Z34="","",IF(INDEX('Quy trinh'!$I$2:$I$300,$Z34)="","",INDEX('Quy trinh'!$I$2:$I$300,$Z34))) | Z34: {=IFERROR(SMALL(IF(('Quy trinh'!$E$2:$E$300<>"Yes")*('Quy trinh'!$C$2:$C$300<>""),ROW('Quy trinh'!$A$2:$A$300)-1),24),"")}
B35: =IF($Z35="","",IF(INDEX('Quy trinh'!$A$2:$A$300,$Z35)="","",INDEX('Quy trinh'!$A$2:$A$300,$Z35))) | C35: =IF($Z35="","",IF(INDEX('Quy trinh'!$C$2:$C$300,$Z35)="","",INDEX('Quy trinh'!$C$2:$C$300,$Z35))) | G35: =IF($Z35="","",IF(INDEX('Quy trinh'!$F$2:$F$300,$Z35)="","",INDEX('Quy trinh'!$F$2:$F$300,$Z35))) | I35: =IF($Z35="","",IF(INDEX('Quy trinh'!$G$2:$G$300,$Z35)="","",INDEX('Quy trinh'!$G$2:$G$300,$Z35))) | J35: =IF($Z35="","",INDEX('Quy trinh'!$H$2:$H$300,$Z35)/100) | K35: =IF($Z35="","",IF(INDEX('Quy trinh'!$I$2:$I$300,$Z35)="","",INDEX('Quy trinh'!$I$2:$I$300,$Z35))) | Z35: {=IFERROR(SMALL(IF(('Quy trinh'!$E$2:$E$300<>"Yes")*('Quy trinh'!$C$2:$C$300<>""),ROW('Quy trinh'!$A$2:$A$300)-1),25),"")}
B36: =IF($Z36="","",IF(INDEX('Quy trinh'!$A$2:$A$300,$Z36)="","",INDEX('Quy trinh'!$A$2:$A$300,$Z36))) | C36: =IF($Z36="","",IF(INDEX('Quy trinh'!$C$2:$C$300,$Z36)="","",INDEX('Quy trinh'!$C$2:$C$300,$Z36))) | G36: =IF($Z36="","",IF(INDEX('Quy trinh'!$F$2:$F$300,$Z36)="","",INDEX('Quy trinh'!$F$2:$F$300,$Z36))) | I36: =IF($Z36="","",IF(INDEX('Quy trinh'!$G$2:$G$300,$Z36)="","",INDEX('Quy trinh'!$G$2:$G$300,$Z36))) | J36: =IF($Z36="","",INDEX('Quy trinh'!$H$2:$H$300,$Z36)/100) | K36: =IF($Z36="","",IF(INDEX('Quy trinh'!$I$2:$I$300,$Z36)="","",INDEX('Quy trinh'!$I$2:$I$300,$Z36))) | Z36: {=IFERROR(SMALL(IF(('Quy trinh'!$E$2:$E$300<>"Yes")*('Quy trinh'!$C$2:$C$300<>""),ROW('Quy trinh'!$A$2:$A$300)-1),26),"")}
B37: =IF($Z37="","",IF(INDEX('Quy trinh'!$A$2:$A$300,$Z37)="","",INDEX('Quy trinh'!$A$2:$A$300,$Z37))) | C37: =IF($Z37="","",IF(INDEX('Quy trinh'!$C$2:$C$300,$Z37)="","",INDEX('Quy trinh'!$C$2:$C$300,$Z37))) | G37: =IF($Z37="","",IF(INDEX('Quy trinh'!$F$2:$F$300,$Z37)="","",INDEX('Quy trinh'!$F$2:$F$300,$Z37))) | I37: =IF($Z37="","",IF(INDEX('Quy trinh'!$G$2:$G$300,$Z37)="","",INDEX('Quy trinh'!$G$2:$G$300,$Z37))) | J37: =IF($Z37="","",INDEX('Quy trinh'!$H$2:$H$300,$Z37)/100) | K37: =IF($Z37="","",IF(INDEX('Quy trinh'!$I$2:$I$300,$Z37)="","",INDEX('Quy trinh'!$I$2:$I$300,$Z37))) | Z37: {=IFERROR(SMALL(IF(('Quy trinh'!$E$2:$E$300<>"Yes")*('Quy trinh'!$C$2:$C$300<>""),ROW('Quy trinh'!$A$2:$A$300)-1),27),"")}
B38: =IF($Z38="","",IF(INDEX('Quy trinh'!$A$2:$A$300,$Z38)="","",INDEX('Quy trinh'!$A$2:$A$300,$Z38))) | C38: =IF($Z38="","",IF(INDEX('Quy trinh'!$C$2:$C$300,$Z38)="","",INDEX('Quy trinh'!$C$2:$C$300,$Z38))) | G38: =IF($Z38="","",IF(INDEX('Quy trinh'!$F$2:$F$300,$Z38)="","",INDEX('Quy trinh'!$F$2:$F$300,$Z38))) | I38: =IF($Z38="","",IF(INDEX('Quy trinh'!$G$2:$G$300,$Z38)="","",INDEX('Quy trinh'!$G$2:$G$300,$Z38))) | J38: =IF($Z38="","",INDEX('Quy trinh'!$H$2:$H$300,$Z38)/100) | K38: =IF($Z38="","",IF(INDEX('Quy trinh'!$I$2:$I$300,$Z38)="","",INDEX('Quy trinh'!$I$2:$I$300,$Z38))) | Z38: {=IFERROR(SMALL(IF(('Quy trinh'!$E$2:$E$300<>"Yes")*('Quy trinh'!$C$2:$C$300<>""),ROW('Quy trinh'!$A$2:$A$300)-1),28),"")}
B39: =IF($Z39="","",IF(INDEX('Quy trinh'!$A$2:$A$300,$Z39)="","",INDEX('Quy trinh'!$A$2:$A$300,$Z39))) | C39: =IF($Z39="","",IF(INDEX('Quy trinh'!$C$2:$C$300,$Z39)="","",INDEX('Quy trinh'!$C$2:$C$300,$Z39))) | G39: =IF($Z39="","",IF(INDEX('Quy trinh'!$F$2:$F$300,$Z39)="","",INDEX('Quy trinh'!$F$2:$F$300,$Z39))) | I39: =IF($Z39="","",IF(INDEX('Quy trinh'!$G$2:$G$300,$Z39)="","",INDEX('Quy trinh'!$G$2:$G$300,$Z39))) | J39: =IF($Z39="","",INDEX('Quy trinh'!$H$2:$H$300,$Z39)/100) | K39: =IF($Z39="","",IF(INDEX('Quy trinh'!$I$2:$I$300,$Z39)="","",INDEX('Quy trinh'!$I$2:$I$300,$Z39))) | Z39: {=IFERROR(SMALL(IF(('Quy trinh'!$E$2:$E$300<>"Yes")*('Quy trinh'!$C$2:$C$300<>""),ROW('Quy trinh'!$A$2:$A$300)-1),29),"")}
B40: =IF($Z40="","",IF(INDEX('Quy trinh'!$A$2:$A$300,$Z40)="","",INDEX('Quy trinh'!$A$2:$A$300,$Z40))) | C40: =IF($Z40="","",IF(INDEX('Quy trinh'!$C$2:$C$300,$Z40)="","",INDEX('Quy trinh'!$C$2:$C$300,$Z40))) | G40: =IF($Z40="","",IF(INDEX('Quy trinh'!$F$2:$F$300,$Z40)="","",INDEX('Quy trinh'!$F$2:$F$300,$Z40))) | I40: =IF($Z40="","",IF(INDEX('Quy trinh'!$G$2:$G$300,$Z40)="","",INDEX('Quy trinh'!$G$2:$G$300,$Z40))) | J40: =IF($Z40="","",INDEX('Quy trinh'!$H$2:$H$300,$Z40)/100) | K40: =IF($Z40="","",IF(INDEX('Quy trinh'!$I$2:$I$300,$Z40)="","",INDEX('Quy trinh'!$I$2:$I$300,$Z40))) | Z40: {=IFERROR(SMALL(IF(('Quy trinh'!$E$2:$E$300<>"Yes")*('Quy trinh'!$C$2:$C$300<>""),ROW('Quy trinh'!$A$2:$A$300)-1),30),"")}
